<!-- <?xml version="1.0"?> -->
<robot name="sprinter" xmlns:xacro="http://www.ros.org/wiki/xacro">

  <!-- Materialdefinitionen -->
  <material name="Grey"><color rgba="0.6 0.6 0.6 1.0"/></material>
  <material name="Blue"><color rgba="0.2 0.2 0.8 1.0"/></material>

  <!-- Welt-Link -->
  <link name="world"/>

  <!-- Basis-Link -->
  <link name="base_link">
    <visual>
      <geometry>
        <box size="0.1 0.1 0.1"/>
      </geometry>
      <material name="Blue"/>
    </visual>
    <collision>
      <geometry>
        <box size="0.1 0.1 0.1"/>
      </geometry>
    </collision>
    <inertial>
      <mass value="15.0"/>
      <inertia ixx="0.5" ixy="0" ixz="0" iyy="0.5" iyz="0" izz="0.5"/>
    </inertial>
  </link>

  <!-- Welt zu Basis -->
  <joint name="world_to_base_joint" type="fixed">
    <parent link="world"/>
    <child link="base_link"/>
    <origin xyz="0 0 1.0" rpy="0 0 0"/>
  </joint>

  <!-- Beine -->
  <link name="left_thigh">
    <visual><geometry><box size="0.05 0.05 0.3"/></geometry></visual>
    <collision><geometry><box size="0.05 0.05 0.3"/></geometry></collision>
    <inertial><mass value="2.0"/><inertia ixx="0.01" iyy="0.01" izz="0.01"/></inertial>
  </link>
  <joint name="left_hip_joint" type="revolute">
    <parent link="base_link"/>
    <child link="left_thigh"/>
    <origin xyz="0.05 0.05 0" rpy="0 0 0"/>
    <axis xyz="0 1 0"/>
    <limit lower="-1.57" upper="1.57" effort="10" velocity="1.0"/>
  </joint>

  <link name="left_shank">
    <visual><geometry><box size="0.04 0.04 0.3"/></geometry></visual>
    <collision><geometry><box size="0.04 0.04 0.3"/></geometry></collision>
    <inertial><mass value="1.5"/><inertia ixx="0.01" iyy="0.01" izz="0.01"/></inertial>
  </link>
  <joint name="left_knee_joint" type="revolute">
    <parent link="left_thigh"/>
    <child link="left_shank"/>
    <origin xyz="0 0 -0.3" rpy="0 0 0"/>
    <axis xyz="0 1 0"/>
    <limit lower="-1.57" upper="1.57" effort="10" velocity="1.0"/>
  </joint>

  <!-- Rechtes Bein -->
  <link name="right_thigh">
    <visual><geometry><box size="0.05 0.05 0.3"/></geometry></visual>
    <collision><geometry><box size="0.05 0.05 0.3"/></geometry></collision>
    <inertial><mass value="2.0"/><inertia ixx="0.01" iyy="0.01" izz="0.01"/></inertial>
  </link>
  <joint name="right_hip_joint" type="revolute">
    <parent link="base_link"/>
    <child link="right_thigh"/>
    <origin xyz="-0.05 -0.05 0" rpy="0 0 0"/>
    <axis xyz="0 1 0"/>
    <limit lower="-1.57" upper="1.57" effort="10" velocity="1.0"/>
  </joint>

  <link name="right_shank">
    <visual><geometry><box size="0.04 0.04 0.3"/></geometry></visual>
    <collision><geometry><box size="0.04 0.04 0.3"/></geometry></collision>
    <inertial><mass value="1.5"/><inertia ixx="0.01" iyy="0.01" izz="0.01"/></inertial>
  </link>
  <joint name="right_knee_joint" type="revolute">
    <parent link="right_thigh"/>
    <child link="right_shank"/>
    <origin xyz="0 0 -0.3" rpy="0 0 0"/>
    <axis xyz="0 1 0"/>
    <limit lower="-1.57" upper="1.57" effort="10" velocity="1.0"/>
  </joint>

  <!-- ros2_control -->
  <ros2_control name="GazeboSystem" type="system">
    <hardware>
      <plugin>gz_ros2_control/GazeboSystem</plugin>
    </hardware>
    <joint name="left_hip_joint">
      <command_interface name="position"/>
      <state_interface name="position"/>
      <state_interface name="velocity"/>
    </joint>
    <joint name="left_knee_joint">
      <command_interface name="position"/>
      <state_interface name="position"/>
      <state_interface name="velocity"/>
    </joint>
    <joint name="right_hip_joint">
      <command_interface name="position"/>
      <state_interface name="position"/>
      <state_interface name="velocity"/>
    </joint>
    <joint name="right_knee_joint">
      <command_interface name="position"/>
      <state_interface name="position"/>
      <state_interface name="velocity"/>
    </joint>
  </ros2_control>

  <!-- Gazebo Plugin -->
  <gazebo>
    <plugin filename="libgz_ros2_control-system.so" name="gz_ros2_control::GazeboSimROS2ControlPlugin">
      <ros>
        <namespace>/sprinter</namespace>
        <parameters>$(find sprinter_control)/config/ros2_control.yaml</parameters>
      </ros>
    </plugin>
  </gazebo>

</robot>
